Workbook

Sheet Portada
B2: BASE DE DATOS TÉCNICA — SACI (INTRUSIÓN) Y SADI (DETECCIÓN DE INCENDIOS)
B3: Plantilla editable · 34 marcas · 32 tipos de dispositivo · 5 variantes por tipo · 8 categorías de equipamiento común · Precios en USD
B5: 34 | C5: 32 | D5: =COUNTA('Base de Datos SACI'!$G$5:$G$1076) -> 1072 | E5: =COUNTA('Base de Datos SADI'!$G$5:$G$716) -> 712 | F5: 8 | G5: =COUNTA(Equipamiento!$F$5:$F$72) -> 68
B6: Marcas (SACI + SADI) | C6: Tipos de dispositivo | D6: Modelos SACI | E6: Modelos SADI | F6: Categorías de equipo | G6: Equipos registrados
B9: Hoja | C9: Contenido
B10: =HYPERLINK("#'Resumen'!B2","Resumen") -> Resumen | C10: Cobertura marca × tipo (SACI y SADI), estadísticas de precios y equipamiento
B11: =HYPERLINK("#'Base de Datos SACI'!B2","Base de Datos SACI") -> Base de Datos SACI | C11: Hoja maestra SACI: 1072 registros (5 variantes por tipo y marca) filtrables
B12: =HYPERLINK("#'Base de Datos SADI'!B2","Base de Datos SADI") -> Base de Datos SADI | C12: Hoja maestra SADI: 712 registros (5 variantes por tipo y marca) filtrables
B13: =HYPERLINK("#'Equipamiento'!B2","Equipamiento") -> Equipamiento | C13: Baterías, fuentes, gabinetes, cableado, herramientas, monitoreo, accesorios y protección
B14: =HYPERLINK("#'Comparativa'!B2","Comparativa") -> Comparativa | C14: Fichas comparativas por tipo (modelo premium / medio / económico)
B15: =HYPERLINK("#'Lista de Precios'!B2","Lista de Precios") -> Lista de Precios | C15: Cotización integral: A SACI + B SADI + C equipamiento, con TOTAL GENERAL
B16: Niveles de marca incluidos
B17: Nivel | C17: Marcas | D17: Enfoque
B18: Alta | C18: Honeywell Security · DSC · Paradox · Bosch Security · Ajax Systems · Visonic · Texecom · Risco · Optex · Siemens · Honeywell Fire · Siemens · Bosch Fire · Edwards (EST) · Simplex (JCI) · Apollo Fire Detectors · Hochiki · Gent (Honeywell) · Xtralis (Honeywell) · Det-Tronics · Fire Sentry (Honeywell) | D18: Fabricantes premium con certificaciones UL/EN y soporte profesional
B19: Media | C19: Crow · Jablotron · Satel · Pyronix (Hikvision) · Hikvision · Qolsys · Morley-IAS (Honeywell) · System Sensor · GST · Fire-Lite (Honeywell) | D19: Relación calidad/precio sólida para proyectos estándar
B20: Entrada | C20: ELDES · Chuango · Zeta Alarm Systems | D20: Opciones económicas para proyectos con presupuesto ajustado
B23: Notas de uso
B24: 1. Las especificaciones y precios son referenciales (USD, mercado 2026); verifique siempre la ficha técnica vigente del fabricante antes de cotizar o instalar.
B25: 2. SACI = Sistemas de Alarma Contra Intrusos (paneles, PIR, contactos, ruptura de vidrio, sirenas, comunicadores, perimetrales, botones de pánico y mandos). SADI = Sistemas de Detección de Incendios (centrales, detectores, estaciones, notificación, módulos de monitoreo/control, terminales repetidoras).
B26: 3. Filas «No disponible en portafolio» (marcadas en gris): la marca no fabrica ese tipo de dispositivo; en Observaciones se sugiere el equivalente de otra marca compatible.
B27: 4. Certificaciones de referencia: SACI — UL 1023/1610, EN 50131 grado 2; SADI — UL 864, EN 54 (partes 2/4/5/7/11/17/20), FM, NFPA 72. Respete la normativa local (NMX, RETIE, etc.).
B28: 5. Use los filtros de la fila de encabezados en las hojas de Base de Datos (panel congelado en H5) y Equipamiento (G5) para segmentar por marca, tipo, nivel o precio.
B29: 6. En Lista de Precios, complete Cantidad y Descuento en las secciones A/B/C; los subtotales y el TOTAL GENERAL se calculan automáticamente.
B30: 7. Las columnas Proveedor y Stock están listas para registrar sus distribuidores locales (listas desplegables en Nivel, Stock y Categoría).
B31: 8. Hoja Comparativa: fichas de los 32 tipos con modelos de referencia por nivel (alto / medio / económico); Aspiración (ASD) incluye 2 especialistas (Xtralis y Honeywell FAAST).
B32: 9. Columnas estructuradas para motor de cálculo (Y en adelante en ambas BD, S en adelante en Equipamiento): consumos en A, tensiones en V, coberturas (m²/m/grados), alturas de montaje, potencia acústica, zonas/particiones/lazos/puntos, sección-ampacidad de cables. Unidades SI; los campos no aplicables a un tipo de equipo quedan como «N/A»; valores referenciales editables.

Sheet Resumen
B2: Resumen — Cobertura Marca × Tipo y Estadísticas de Precios
B5: Tipo de Dispositivo \ Marca | C5: Honeywell Security | D5: DSC | E5: Paradox | F5: Bosch Security | G5: Ajax Systems | H5: Visonic | I5: Texecom | J5: Risco | K5: Crow | L5: Jablotron | M5: Satel | N5: Pyronix (Hikvision) | O5: Hikvision | P5: Qolsys | Q5: ELDES | R5: Chuango | S5: Optex | T5: Siemens | U5: Total
B6: Panel híbrido | C6: =COUNTIFS('Base de Datos SACI'!$C$5:$C$1076,C$5,'Base de Datos SACI'!$F$5:$F$1076,$B6,'Base de Datos SACI'!$G$5:$G$1076,"<>*No disponible*") -> 5 | D6: =COUNTIFS('Base de Datos SACI'!$C$5:$C$1076,D$5,'Base de Datos SACI'!$F$5:$F$1076,$B6,'Base de Datos SACI'!$G$5:$G$1076,"<>*No disponible*") -> 5 | E6: =COUNTIFS('Base de Datos SACI'!$C$5:$C$1076,E$5,'Base de Datos SACI'!$F$5:$F$1076,$B6,'Base de Datos SACI'!$G$5:$G$1076,"<>*No disponible*") -> 5 | F6: =COUNTIFS('Base de Datos SACI'!$C$5:$C$1076,F$5,'Base de Datos SACI'!$F$5:$F$1076,$B6,'Base de Datos SACI'!$G$5:$G$1076,"<>*No disponible*") -> 5 | G6: =COUNTIFS('Base de Datos SACI'!$C$5:$C$1076,G$5,'Base de Datos SACI'!$F$5:$F$1076,$B6,'Base de Datos SACI'!$G$5:$G$1076,"<>*No disponible*") -> 0 | H6: =COUNTIFS('Base de Datos SACI'!$C$5:$C$1076,H$5,'Base de Datos SACI'!$F$5:$F$1076,$B6,'Base de Datos SACI'!$G$5:$G$1076,"<>*No disponible*") -> 0 | I6: =COUNTIFS('Base de Datos SACI'!$C$5:$C$1076,I$5,'Base de Datos SACI'!$F$5:$F$1076,$B6,'Base de Datos SACI'!$G$5:$G$1076,"<>*No disponible*") -> 5 | J6: =COUNTIFS('Base de Datos SACI'!$C$5:$C$1076,J$5,'Base de Datos SACI'!$F$5:$F$1076,$B6,'Base de Datos SACI'!$G$5:$G$1076,"<>*No disponible*") -> 5 | ... T6: =COUNTIFS('Base de Datos SACI'!$C$5:$C$1076,T$5,'Base de Datos SACI'!$F$5:$F$1076,$B6,'Base de Datos SACI'!$G$5:$G$1076,"<>*No disponible*") -> 5 | U6: =SUM(C6:T6) -> 65
B7: Panel alámbrico | C7: =COUNTIFS('Base de Datos SACI'!$C$5:$C$1076,C$5,'Base de Datos SACI'!$F$5:$F$1076,$B7,'Base de Datos SACI'!$G$5:$G$1076,"<>*No disponible*") -> 5 | D7: =COUNTIFS('Base de Datos SACI'!$C$5:$C$1076,D$5,'Base de Datos SACI'!$F$5:$F$1076,$B7,'Base de Datos SACI'!$G$5:$G$1076,"<>*No disponible*") -> 5 | E7: =COUNTIFS('Base de Datos SACI'!$C$5:$C$1076,E$5,'Base de Datos SACI'!$F$5:$F$1076,$B7,'Base de Datos SACI'!$G$5:$G$1076,"<>*No disponible*") -> 5 | F7: =COUNTIFS('Base de Datos SACI'!$C$5:$C$1076,F$5,'Base de Datos SACI'!$F$5:$F$1076,$B7,'Base de Datos SACI'!$G$5:$G$1076,"<>*No disponible*") -> 5 | G7: =COUNTIFS('Base de Datos SACI'!$C$5:$C$1076,G$5,'Base de Datos SACI'!$F$5:$F$1076,$B7,'Base de Datos SACI'!$G$5:$G$1076,"<>*No disponible*") -> 0 | H7: =COUNTIFS('Base de Datos SACI'!$C$5:$C$1076,H$5,'Base de Datos SACI'!$F$5:$F$1076,$B7,'Base de Datos SACI'!$G$5:$G$1076,"<>*No disponible*") -> 0 | I7: =COUNTIFS('Base de Datos SACI'!$C$5:$C$1076,I$5,'Base de Datos SACI'!$F$5:$F$1076,$B7,'Base de Datos SACI'!$G$5:$G$1076,"<>*No disponible*") -> 5 | J7: =COUNTIFS('Base de Datos SACI'!$C$5:$C$1076,J$5,'Base de Datos SACI'!$F$5:$F$1076,$B7,'Base de Datos SACI'!$G$5:$G$1076,"<>*No disponible*") -> 0 | ... T7: =COUNTIFS('Base de Datos SACI'!$C$5:$C$1076,T$5,'Base de Datos SACI'!$F$5:$F$1076,$B7,'Base de Datos SACI'!$G$5:$G$1076,"<>*No disponible*") -> 0 | U7: =SUM(C7:T7) -> 45
B8: Panel inalámbrico / Hub | C8: =COUNTIFS('Base de Datos SACI'!$C$5:$C$1076,C$5,'Base de Datos SACI'!$F$5:$F$1076,$B8,'Base de Datos SACI'!$G$5:$G$1076,"<>*No disponible*") -> 5 | D8: =COUNTIFS('Base de Datos SACI'!$C$5:$C$1076,D$5,'Base de Datos SACI'!$F$5:$F$1076,$B8,'Base de Datos SACI'!$G$5:$G$1076,"<>*No disponible*") -> 5 | E8: =COUNTIFS('Base de Datos SACI'!$C$5:$C$1076,E$5,'Base de Datos SACI'!$F$5:$F$1076,$B8,'Base de Datos SACI'!$G$5:$G$1076,"<>*No disponible*") -> 5 | F8: =COUNTIFS('Base de Datos SACI'!$C$5:$C$1076,F$5,'Base de Datos SACI'!$F$5:$F$1076,$B8,'Base de Datos SACI'!$G$5:$G$1076,"<>*No disponible*") -> 5 | G8: =COUNTIFS('Base de Datos SACI'!$C$5:$C$1076,G$5,'Base de Datos SACI'!$F$5:$F$1076,$B8,'Base de Datos SACI'!$G$5:$G$1076,"<>*No disponible*") -> 5 | H8: =COUNTIFS('Base de Datos SACI'!$C$5:$C$1076,H$5,'Base de Datos SACI'!$F$5:$F$1076,$B8,'Base de Datos SACI'!$G$5:$G$1076,"<>*No disponible*") -> 5 | I8: =COUNTIFS('Base de Datos SACI'!$C$5:$C$1076,I$5,'Base de Datos SACI'!$F$5:$F$1076,$B8,'Base de Datos SACI'!$G$5:$G$1076,"<>*No disponible*") -> 0 | J8: =COUNTIFS('Base de Datos SACI'!$C$5:$C$1076,J$5,'Base de Datos SACI'!$F$5:$F$1076,$B8,'Base de Datos SACI'!$G$5:$G$1076,"<>*No disponible*") -> 5 | ... T8: =COUNTIFS('Base de Datos SACI'!$C$5:$C$1076,T$5,'Base de Datos SACI'!$F$5:$F$1076,$B8,'Base de Datos SACI'!$G$5:$G$1076,"<>*No disponible*") -> 0 | U8: =SUM(C8:T8) -> 60
B9: Teclado de control | C9: =COUNTIFS('Base de Datos SACI'!$C$5:$C$1076,C$5,'Base de Datos SACI'!$F$5:$F$1076,$B9,'Base de Datos SACI'!$G$5:$G$1076,"<>*No disponible*") -> 5 | D9: =COUNTIFS('Base de Datos SACI'!$C$5:$C$1076,D$5,'Base de Datos SACI'!$F$5:$F$1076,$B9,'Base de Datos SACI'!$G$5:$G$1076,"<>*No disponible*") -> 5 | E9: =COUNTIFS('Base de Datos SACI'!$C$5:$C$1076,E$5,'Base de Datos SACI'!$F$5:$F$1076,$B9,'Base de Datos SACI'!$G$5:$G$1076,"<>*No disponible*") -> 5 | F9: =COUNTIFS('Base de Datos SACI'!$C$5:$C$1076,F$5,'Base de Datos SACI'!$F$5:$F$1076,$B9,'Base de Datos SACI'!$G$5:$G$1076,"<>*No disponible*") -> 5 | G9: =COUNTIFS('Base de Datos SACI'!$C$5:$C$1076,G$5,'Base de Datos SACI'!$F$5:$F$1076,$B9,'Base de Datos SACI'!$G$5:$G$1076,"<>*No disponible*") -> 5 | H9: =COUNTIFS('Base de Datos SACI'!$C$5:$C$1076,H$5,'Base de Datos SACI'!$F$5:$F$1076,$B9,'Base de Datos SACI'!$G$5:$G$1076,"<>*No disponible*") -> 5 | I9: =COUNTIFS('Base de Datos SACI'!$C$5:$C$1076,I$5,'Base de Datos SACI'!$F$5:$F$1076,$B9,'Base de Datos SACI'!$G$5:$G$1076,"<>*No disponible*") -> 5 | J9: =COUNTIFS('Base de Datos SACI'!$C$5:$C$1076,J$5,'Base de Datos SACI'!$F$5:$F$1076,$B9,'Base de Datos SACI'!$G$5:$G$1076,"<>*No disponible*") -> 5 | ... T9: =COUNTIFS('Base de Datos SACI'!$C$5:$C$1076,T$5,'Base de Datos SACI'!$F$5:$F$1076,$B9,'Base de Datos SACI'!$G$5:$G$1076,"<>*No disponible*") -> 5 | U9: =SUM(C9:T9) -> 85
B10: Detector PIR interior | C10: =COUNTIFS('Base de Datos SACI'!$C$5:$C$1076,C$5,'Base de Datos SACI'!$F$5:$F$1076,$B10,'Base de Datos SACI'!$G$5:$G$1076,"<>*No disponible*") -> 5 | D10: =COUNTIFS('Base de Datos SACI'!$C$5:$C$1076,D$5,'Base de Datos SACI'!$F$5:$F$1076,$B10,'Base de Datos SACI'!$G$5:$G$1076,"<>*No disponible*") -> 5 | E10: =COUNTIFS('Base de Datos SACI'!$C$5:$C$1076,E$5,'Base de Datos SACI'!$F$5:$F$1076,$B10,'Base de Datos SACI'!$G$5:$G$1076,"<>*No disponible*") -> 5 | F10: =COUNTIFS('Base de Datos SACI'!$C$5:$C$1076,F$5,'Base de Datos SACI'!$F$5:$F$1076,$B10,'Base de Datos SACI'!$G$5:$G$1076,"<>*No disponible*") -> 5 | G10: =COUNTIFS('Base de Datos SACI'!$C$5:$C$1076,G$5,'Base de Datos SACI'!$F$5:$F$1076,$B10,'Base de Datos SACI'!$G$5:$G$1076,"<>*No disponible*") -> 5 | H10: =COUNTIFS('Base de Datos SACI'!$C$5:$C$1076,H$5,'Base de Datos SACI'!$F$5:$F$1076,$B10,'Base de Datos SACI'!$G$5:$G$1076,"<>*No disponible*") -> 5 | I10: =COUNTIFS('Base de Datos SACI'!$C$5:$C$1076,I$5,'Base de Datos SACI'!$F$5:$F$1076,$B10,'Base de Datos SACI'!$G$5:$G$1076,"<>*No disponible*") -> 5 | J10: =COUNTIFS('Base de Datos SACI'!$C$5:$C$1076,J$5,'Base de Datos SACI'!$F$5:$F$1076,$B10,'Base de Datos SACI'!$G$5:$G$1076,"<>*No disponible*") -> 5 | ... T10: =COUNTIFS('Base de Datos SACI'!$C$5:$C$1076,T$5,'Base de Datos SACI'!$F$5:$F$1076,$B10,'Base de Datos SACI'!$G$5:$G$1076,"<>*No disponible*") -> 0 | U10: =SUM(C10:T10) -> 85
B11: PIR inalámbrico | C11: =COUNTIFS('Base de Datos SACI'!$C$5:$C$1076,C$5,'Base de Datos SACI'!$F$5:$F$1076,$B11,'Base de Datos SACI'!$G$5:$G$1076,"<>*No disponible*") -> 5 | D11: =COUNTIFS('Base de Datos SACI'!$C$5:$C$1076,D$5,'Base de Datos SACI'!$F$5:$F$1076,$B11,'Base de Datos SACI'!$G$5:$G$1076,"<>*No disponible*") -> 5 | E11: =COUNTIFS('Base de Datos SACI'!$C$5:$C$1076,E$5,'Base de Datos SACI'!$F$5:$F$1076,$B11,'Base de Datos SACI'!$G$5:$G$1076,"<>*No disponible*") -> 5 | F11: =COUNTIFS('Base de Datos SACI'!$C$5:$C$1076,F$5,'Base de Datos SACI'!$F$5:$F$1076,$B11,'Base de Datos SACI'!$G$5:$G$1076,"<>*No disponible*") -> 5 | G11: =COUNTIFS('Base de Datos SACI'!$C$5:$C$1076,G$5,'Base de Datos SACI'!$F$5:$F$1076,$B11,'Base de Datos SACI'!$G$5:$G$1076,"<>*No disponible*") -> 5 | H11: =COUNTIFS('Base de Datos SACI'!$C$5:$C$1076,H$5,'Base de Datos SACI'!$F$5:$F$1076,$B11,'Base de Datos SACI'!$G$5:$G$1076,"<>*No disponible*") -> 5 | I11: =COUNTIFS('Base de Datos SACI'!$C$5:$C$1076,I$5,'Base de Datos SACI'!$F$5:$F$1076,$B11,'Base de Datos SACI'!$G$5:$G$1076,"<>*No disponible*") -> 5 | J11: =COUNTIFS('Base de Datos SACI'!$C$5:$C$1076,J$5,'Base de Datos SACI'!$F$5:$F$1076,$B11,'Base de Datos SACI'!$G$5:$G$1076,"<>*No disponible*") -> 5 | ... T11: =COUNTIFS('Base de Datos SACI'!$C$5:$C$1076,T$5,'Base de Datos SACI'!$F$5:$F$1076,$B11,'Base de Datos SACI'!$G$5:$G$1076,"<>*No disponible*") -> 5 | U11: =SUM(C11:T11) -> 80
B12: Doble tecnología / exterior | C12: =COUNTIFS('Base de Datos SACI'!$C$5:$C$1076,C$5,'Base de Datos SACI'!$F$5:$F$1076,$B12,'Base de Datos SACI'!$G$5:$G$1076,"<>*No disponible*") -> 5 | D12: =COUNTIFS('Base de Datos SACI'!$C$5:$C$1076,D$5,'Base de Datos SACI'!$F$5:$F$1076,$B12,'Base de Datos SACI'!$G$5:$G$1076,"<>*No disponible*") -> 5 | E12: =COUNTIFS('Base de Datos SACI'!$C$5:$C$1076,E$5,'Base de Datos SACI'!$F$5:$F$1076,$B12,'Base de Datos SACI'!$G$5:$G$1076,"<>*No disponible*") -> 5 | F12: =COUNTIFS('Base de Datos SACI'!$C$5:$C$1076,F$5,'Base de Datos SACI'!$F$5:$F$1076,$B12,'Base de Datos SACI'!$G$5:$G$1076,"<>*No disponible*") -> 5 | G12: =COUNTIFS('Base de Datos SACI'!$C$5:$C$1076,G$5,'Base de Datos SACI'!$F$5:$F$1076,$B12,'Base de Datos SACI'!$G$5:$G$1076,"<>*No disponible*") -> 5 | H12: =COUNTIFS('Base de Datos SACI'!$C$5:$C$1076,H$5,'Base de Datos SACI'!$F$5:$F$1076,$B12,'Base de Datos SACI'!$G$5:$G$1076,"<>*No disponible*") -> 5 | I12: =COUNTIFS('Base de Datos SACI'!$C$5:$C$1076,I$5,'Base de Datos SACI'!$F$5:$F$1076,$B12,'Base de Datos SACI'!$G$5:$G$1076,"<>*No disponible*") -> 5 | J12: =COUNTIFS('Base de Datos SACI'!$C$5:$C$1076,J$5,'Base de Datos SACI'!$F$5:$F$1076,$B12,'Base de Datos SACI'!$G$5:$G$1076,"<>*No disponible*") -> 5 | ... T12: =COUNTIFS('Base de Datos SACI'!$C$5:$C$1076,T$5,'Base de Datos SACI'!$F$5:$F$1076,$B12,'Base de Datos SACI'!$G$5:$G$1076,"<>*No disponible*") -> 0 | U12: =SUM(C12:T12) -> 70
B13: Contacto magnético | C13: =COUNTIFS('Base de Datos SACI'!$C$5:$C$1076,C$5,'Base de Datos SACI'!$F$5:$F$1076,$B13,'Base de Datos SACI'!$G$5:$G$1076,"<>*No disponible*") -> 5 | D13: =COUNTIFS('Base de Datos SACI'!$C$5:$C$1076,D$5,'Base de Datos SACI'!$F$5:$F$1076,$B13,'Base de Datos SACI'!$G$5:$G$1076,"<>*No disponible*") -> 5 | E13: =COUNTIFS('Base de Datos SACI'!$C$5:$C$1076,E$5,'Base de Datos SACI'!$F$5:$F$1076,$B13,'Base de Datos SACI'!$G$5:$G$1076,"<>*No disponible*") -> 5 | F13: =COUNTIFS('Base de Datos SACI'!$C$5:$C$1076,F$5,'Base de Datos SACI'!$F$5:$F$1076,$B13,'Base de Datos SACI'!$G$5:$G$1076,"<>*No disponible*") -> 5 | G13: =COUNTIFS('Base de Datos SACI'!$C$5:$C$1076,G$5,'Base de Datos SACI'!$F$5:$F$1076,$B13,'Base de Datos SACI'!$G$5:$G$1076,"<>*No disponible*") -> 5 | H13: =COUNTIFS('Base de Datos SACI'!$C$5:$C$1076,H$5,'Base de Datos SACI'!$F$5:$F$1076,$B13,'Base de Datos SACI'!$G$5:$G$1076,"<>*No disponible*") -> 5 | I13: =COUNTIFS('Base de Datos SACI'!$C$5:$C$1076,I$5,'Base de Datos SACI'!$F$5:$F$1076,$B13,'Base de Datos SACI'!$G$5:$G$1076,"<>*No disponible*") -> 5 | J13: =COUNTIFS('Base de Datos SACI'!$C$5:$C$1076,J$5,'Base de Datos SACI'!$F$5:$F$1076,$B13,'Base de Datos SACI'!$G$5:$G$1076,"<>*No disponible*") -> 5 | ... T13: =COUNTIFS('Base de Datos SACI'!$C$5:$C$1076,T$5,'Base de Datos SACI'!$F$5:$F$1076,$B13,'Base de Datos SACI'!$G$5:$G$1076,"<>*No disponible*") -> 5 | U13: =SUM(C13:T13) -> 85
B14: Ruptura de vidrio | C14: =COUNTIFS('Base de Datos SACI'!$C$5:$C$1076,C$5,'Base de Datos SACI'!$F$5:$F$1076,$B14,'Base de Datos SACI'!$G$5:$G$1076,"<>*No disponible*") -> 5 | D14: =COUNTIFS('Base de Datos SACI'!$C$5:$C$1076,D$5,'Base de Datos SACI'!$F$5:$F$1076,$B14,'Base de Datos SACI'!$G$5:$G$1076,"<>*No disponible*") -> 5 | E14: =COUNTIFS('Base de Datos SACI'!$C$5:$C$1076,E$5,'Base de Datos SACI'!$F$5:$F$1076,$B14,'Base de Datos SACI'!$G$5:$G$1076,"<>*No disponible*") -> 5 | F14: =COUNTIFS('Base de Datos SACI'!$C$5:$C$1076,F$5,'Base de Datos SACI'!$F$5:$F$1076,$B14,'Base de Datos SACI'!$G$5:$G$1076,"<>*No disponible*") -> 5 | G14: =COUNTIFS('Base de Datos SACI'!$C$5:$C$1076,G$5,'Base de Datos SACI'!$F$5:$F$1076,$B14,'Base de Datos SACI'!$G$5:$G$1076,"<>*No disponible*") -> 5 | H14: =COUNTIFS('Base de Datos SACI'!$C$5:$C$1076,H$5,'Base de Datos SACI'!$F$5:$F$1076,$B14,'Base de Datos SACI'!$G$5:$G$1076,"<>*No disponible*") -> 5 | I14: =COUNTIFS('Base de Datos SACI'!$C$5:$C$1076,I$5,'Base de Datos SACI'!$F$5:$F$1076,$B14,'Base de Datos SACI'!$G$5:$G$1076,"<>*No disponible*") -> 0 | J14: =COUNTIFS('Base de Datos SACI'!$C$5:$C$1076,J$5,'Base de Datos SACI'!$F$5:$F$1076,$B14,'Base de Datos SACI'!$G$5:$G$1076,"<>*No disponible*") -> 0 | ... T14: =COUNTIFS('Base de Datos SACI'!$C$5:$C$1076,T$5,'Base de Datos SACI'!$F$5:$F$1076,$B14,'Base de Datos SACI'!$G$5:$G$1076,"<>*No disponible*") -> 5 | U14: =SUM(C14:T14) -> 40
B15: Sirena exterior | C15: =COUNTIFS('Base de Datos SACI'!$C$5:$C$1076,C$5,'Base de Datos SACI'!$F$5:$F$1076,$B15,'Base de Datos SACI'!$G$5:$G$1076,"<>*No disponible*") -> 5 | D15: =COUNTIFS('Base de Datos SACI'!$C$5:$C$1076,D$5,'Base de Datos SACI'!$F$5:$F$1076,$B15,'Base de Datos SACI'!$G$5:$G$1076,"<>*No disponible*") -> 5 | E15: =COUNTIFS('Base de Datos SACI'!$C$5:$C$1076,E$5,'Base de Datos SACI'!$F$5:$F$1076,$B15,'Base de Datos SACI'!$G$5:$G$1076,"<>*No disponible*") -> 5 | F15: =COUNTIFS('Base de Datos SACI'!$C$5:$C$1076,F$5,'Base de Datos SACI'!$F$5:$F$1076,$B15,'Base de Datos SACI'!$G$5:$G$1076,"<>*No disponible*") -> 5 | G15: =COUNTIFS('Base de Datos SACI'!$C$5:$C$1076,G$5,'Base de Datos SACI'!$F$5:$F$1076,$B15,'Base de Datos SACI'!$G$5:$G$1076,"<>*No disponible*") -> 5 | H15: =COUNTIFS('Base de Datos SACI'!$C$5:$C$1076,H$5,'Base de Datos SACI'!$F$5:$F$1076,$B15,'Base de Datos SACI'!$G$5:$G$1076,"<>*No disponible*") -> 5 | I15: =COUNTIFS('Base de Datos SACI'!$C$5:$C$1076,I$5,'Base de Datos SACI'!$F$5:$F$1076,$B15,'Base de Datos SACI'!$G$5:$G$1076,"<>*No disponible*") -> 5 | J15: =COUNTIFS('Base de Datos SACI'!$C$5:$C$1076,J$5,'Base de Datos SACI'!$F$5:$F$1076,$B15,'Base de Datos SACI'!$G$5:$G$1076,"<>*No disponible*") -> 5 | ... T15: =COUNTIFS('Base de Datos SACI'!$C$5:$C$1076,T$5,'Base de Datos SACI'!$F$5:$F$1076,$B15,'Base de Datos SACI'!$G$5:$G$1076,"<>*No disponible*") -> 5 | U15: =SUM(C15:T15) -> 80
B16: Sirena interior | C16: =COUNTIFS('Base de Datos SACI'!$C$5:$C$1076,C$5,'Base de Datos SACI'!$F$5:$F$1076,$B16,'Base de Datos SACI'!$G$5:$G$1076,"<>*No disponible*") -> 5 | D16: =COUNTIFS('Base de Datos SACI'!$C$5:$C$1076,D$5,'Base de Datos SACI'!$F$5:$F$1076,$B16,'Base de Datos SACI'!$G$5:$G$1076,"<>*No disponible*") -> 5 | E16: =COUNTIFS('Base de Datos SACI'!$C$5:$C$1076,E$5,'Base de Datos SACI'!$F$5:$F$1076,$B16,'Base de Datos SACI'!$G$5:$G$1076,"<>*No disponible*") -> 5 | F16: =COUNTIFS('Base de Datos SACI'!$C$5:$C$1076,F$5,'Base de Datos SACI'!$F$5:$F$1076,$B16,'Base de Datos SACI'!$G$5:$G$1076,"<>*No disponible*") -> 5 | G16: =COUNTIFS('Base de Datos SACI'!$C$5:$C$1076,G$5,'Base de Datos SACI'!$F$5:$F$1076,$B16,'Base de Datos SACI'!$G$5:$G$1076,"<>*No disponible*") -> 5 | H16: =COUNTIFS('Base de Datos SACI'!$C$5:$C$1076,H$5,'Base de Datos SACI'!$F$5:$F$1076,$B16,'Base de Datos SACI'!$G$5:$G$1076,"<>*No disponible*") -> 5 | I16: =COUNTIFS('Base de Datos SACI'!$C$5:$C$1076,I$5,'Base de Datos SACI'!$F$5:$F$1076,$B16,'Base de Datos SACI'!$G$5:$G$1076,"<>*No disponible*") -> 5 | J16: =COUNTIFS('Base de Datos SACI'!$C$5:$C$1076,J$5,'Base de Datos SACI'!$F$5:$F$1076,$B16,'Base de Datos SACI'!$G$5:$G$1076,"<>*No disponible*") -> 5 | ... T16: =COUNTIFS('Base de Datos SACI'!$C$5:$C$1076,T$5,'Base de Datos SACI'!$F$5:$F$1076,$B16,'Base de Datos SACI'!$G$5:$G$1076,"<>*No disponible*") -> 5 | U16: =SUM(C16:T16) -> 65
B17: Comunicador de eventos | C17: =COUNTIFS('Base de Datos SACI'!$C$5:$C$1076,C$5,'Base de Datos SACI'!$F$5:$F$1076,$B17,'Base de Datos SACI'!$G$5:$G$1076,"<>*No disponible*") -> 5 | D17: =COUNTIFS('Base de Datos SACI'!$C$5:$C$1076,D$5,'Base de Datos SACI'!$F$5:$F$1076,$B17,'Base de Datos SACI'!$G$5:$G$1076,"<>*No disponible*") -> 5 | E17: =COUNTIFS('Base de Datos SACI'!$C$5:$C$1076,E$5,'Base de Datos SACI'!$F$5:$F$1076,$B17,'Base de Datos SACI'!$G$5:$G$1076,"<>*No disponible*") -> 5 | F17: =COUNTIFS('Base de Datos SACI'!$C$5:$C$1076,F$5,'Base de Datos SACI'!$F$5:$F$1076,$B17,'Base de Datos SACI'!$G$5:$G$1076,"<>*No disponible*") -> 5 | G17: =COUNTIFS('Base de Datos SACI'!$C$5:$C$1076,G$5,'Base de Datos SACI'!$F$5:$F$1076,$B17,'Base de Datos SACI'!$G$5:$G$1076,"<>*No disponible*") -> 5 | H17: =COUNTIFS('Base de Datos SACI'!$C$5:$C$1076,H$5,'Base de Datos SACI'!$F$5:$F$1076,$B17,'Base de Datos SACI'!$G$5:$G$1076,"<>*No disponible*") -> 5 | I17: =COUNTIFS('Base de Datos SACI'!$C$5:$C$1076,I$5,'Base de Datos SACI'!$F$5:$F$1076,$B17,'Base de Datos SACI'!$G$5:$G$1076,"<>*No disponible*") -> 5 | J17: =COUNTIFS('Base de Datos SACI'!$C$5:$C$1076,J$5,'Base de Datos SACI'!$F$5:$F$1076,$B17,'Base de Datos SACI'!$G$5:$G$1076,"<>*No disponible*") -> 5 | ... T17: =COUNTIFS('Base de Datos SACI'!$C$5:$C$1076,T$5,'Base de Datos SACI'!$F$5:$F$1076,$B17,'Base de Datos SACI'!$G$5:$G$1076,"<>*No disponible*") -> 5 | U17: =SUM(C17:T17) -> 65
... B21: Mando inalámbrico | C21: =COUNTIFS('Base de Datos SACI'!$C$5:$C$1076,C$5,'Base de Datos SACI'!$F$5:$F$1076,$B21,'Base de Datos SACI'!$G$5:$G$1076,"<>*No disponible*") -> 5 | D21: =COUNTIFS('Base de Datos SACI'!$C$5:$C$1076,D$5,'Base de Datos SACI'!$F$5:$F$1076,$B21,'Base de Datos SACI'!$G$5:$G$1076,"<>*No disponible*") -> 5 | E21: =COUNTIFS('Base de Datos SACI'!$C$5:$C$1076,E$5,'Base de Datos SACI'!$F$5:$F$1076,$B21,'Base de Datos SACI'!$G$5:$G$1076,"<>*No disponible*") -> 5 | F21: =COUNTIFS('Base de Datos SACI'!$C$5:$C$1076,F$5,'Base de Datos SACI'!$F$5:$F$1076,$B21,'Base de Datos SACI'!$G$5:$G$1076,"<>*No disponible*") -> 0 | G21: =COUNTIFS('Base de Datos SACI'!$C$5:$C$1076,G$5,'Base de Datos SACI'!$F$5:$F$1076,$B21,'Base de Datos SACI'!$G$5:$G$1076,"<>*No disponible*") -> 5 | H21: =COUNTIFS('Base de Datos SACI'!$C$5:$C$1076,H$5,'Base de Datos SACI'!$F$5:$F$1076,$B21,'Base de Datos SACI'!$G$5:$G$1076,"<>*No disponible*") -> 5 | I21: =COUNTIFS('Base de Datos SACI'!$C$5:$C$1076,I$5,'Base de Datos SACI'!$F$5:$F$1076,$B21,'Base de Datos SACI'!$G$5:$G$1076,"<>*No disponible*") -> 5 | J21: =COUNTIFS('Base de Datos SACI'!$C$5:$C$1076,J$5,'Base de Datos SACI'!$F$5:$F$1076,$B21,'Base de Datos SACI'!$G$5:$G$1076,"<>*No disponible*") -> 0 | ... T21: =COUNTIFS('Base de Datos SACI'!$C$5:$C$1076,T$5,'Base de Datos SACI'!$F$5:$F$1076,$B21,'Base de Datos SACI'!$G$5:$G$1076,"<>*No disponible*") -> 5 | U21: =SUM(C21:T21) -> 50
B22: Modelos activos por marca | C22: =SUM(C6:C21) -> 75 | D22: =SUM(D6:D21) -> 75 | E22: =SUM(E6:E21) -> 70 | F22: =SUM(F6:F21) -> 65 | G22: =SUM(G6:G21) -> 65 | H22: =SUM(H6:H21) -> 65 | I22: =SUM(I6:I21) -> 60 | J22: =SUM(J6:J21) -> 60 | ... U22: =SUM(U6:U21) -> 980
B25: Cobertura SADI — Detectores y Centrales de Incendios
B26: Tipo de Dispositivo \ Marca | C26: Honeywell Fire | D26: Siemens | E26: Bosch Fire | F26: Edwards (EST) | G26: Simplex (JCI) | H26: Morley-IAS (Honeywell) | I26: Apollo Fire Detectors | J26: Hochiki | K26: System Sensor | L26: GST | M26: Fire-Lite (Honeywell) | N26: Zeta Alarm Systems | O26: Gent (Honeywell) | P26: Xtralis (Honeywell) | Q26: Det-Tronics | R26: Fire Sentry (Honeywell) | S26: Total
B27: Panel direccionable | C27: =COUNTIFS('Base de Datos SADI'!$C$5:$C$716,C$26,'Base de Datos SADI'!$F$5:$F$716,$B27,'Base de Datos SADI'!$G$5:$G$716,"<>*No disponible*") -> 5 | D27: =COUNTIFS('Base de Datos SADI'!$C$5:$C$716,D$26,'Base de Datos SADI'!$F$5:$F$716,$B27,'Base de Datos SADI'!$G$5:$G$716,"<>*No disponible*") -> 5 | E27: =COUNTIFS('Base de Datos SADI'!$C$5:$C$716,E$26,'Base de Datos SADI'!$F$5:$F$716,$B27,'Base de Datos SADI'!$G$5:$G$716,"<>*No disponible*") -> 5 | F27: =COUNTIFS('Base de Datos SADI'!$C$5:$C$716,F$26,'Base de Datos SADI'!$F$5:$F$716,$B27,'Base de Datos SADI'!$G$5:$G$716,"<>*No disponible*") -> 5 | G27: =COUNTIFS('Base de Datos SADI'!$C$5:$C$716,G$26,'Base de Datos SADI'!$F$5:$F$716,$B27,'Base de Datos SADI'!$G$5:$G$716,"<>*No disponible*") -> 5 | H27: =COUNTIFS('Base de Datos SADI'!$C$5:$C$716,H$26,'Base de Datos SADI'!$F$5:$F$716,$B27,'Base de Datos SADI'!$G$5:$G$716,"<>*No disponible*") -> 5 | I27: =COUNTIFS('Base de Datos SADI'!$C$5:$C$716,I$26,'Base de Datos SADI'!$F$5:$F$716,$B27,'Base de Datos SADI'!$G$5:$G$716,"<>*No disponible*") -> 0 | J27: =COUNTIFS('Base de Datos SADI'!$C$5:$C$716,J$26,'Base de Datos SADI'!$F$5:$F$716,$B27,'Base de Datos SADI'!$G$5:$G$716,"<>*No disponible*") -> 0 | ... R27: =COUNTIFS('Base de Datos SADI'!$C$5:$C$716,R$26,'Base de Datos SADI'!$F$5:$F$716,$B27,'Base de Datos SADI'!$G$5:$G$716,"<>*No disponible*") -> 0 | S27: =SUM(C27:R27) -> 50
B28: Panel convencional | C28: =COUNTIFS('Base de Datos SADI'!$C$5:$C$716,C$26,'Base de Datos SADI'!$F$5:$F$716,$B28,'Base de Datos SADI'!$G$5:$G$716,"<>*No disponible*") -> 0 | D28: =COUNTIFS('Base de Datos SADI'!$C$5:$C$716,D$26,'Base de Datos SADI'!$F$5:$F$716,$B28,'Base de Datos SADI'!$G$5:$G$716,"<>*No disponible*") -> 0 | E28: =COUNTIFS('Base de Datos SADI'!$C$5:$C$716,E$26,'Base de Datos SADI'!$F$5:$F$716,$B28,'Base de Datos SADI'!$G$5:$G$716,"<>*No disponible*") -> 5 | F28: =COUNTIFS('Base de Datos SADI'!$C$5:$C$716,F$26,'Base de Datos SADI'!$F$5:$F$716,$B28,'Base de Datos SADI'!$G$5:$G$716,"<>*No disponible*") -> 5 | G28: =COUNTIFS('Base de Datos SADI'!$C$5:$C$716,G$26,'Base de Datos SADI'!$F$5:$F$716,$B28,'Base de Datos SADI'!$G$5:$G$716,"<>*No disponible*") -> 5 | H28: =COUNTIFS('Base de Datos SADI'!$C$5:$C$716,H$26,'Base de Datos SADI'!$F$5:$F$716,$B28,'Base de Datos SADI'!$G$5:$G$716,"<>*No disponible*") -> 5 | I28: =COUNTIFS('Base de Datos SADI'!$C$5:$C$716,I$26,'Base de Datos SADI'!$F$5:$F$716,$B28,'Base de Datos SADI'!$G$5:$G$716,"<>*No disponible*") -> 0 | J28: =COUNTIFS('Base de Datos SADI'!$C$5:$C$716,J$26,'Base de Datos SADI'!$F$5:$F$716,$B28,'Base de Datos SADI'!$G$5:$G$716,"<>*No disponible*") -> 0 | ... R28: =COUNTIFS('Base de Datos SADI'!$C$5:$C$716,R$26,'Base de Datos SADI'!$F$5:$F$716,$B28,'Base de Datos SADI'!$G$5:$G$716,"<>*No disponible*") -> 0 | S28: =SUM(C28:R28) -> 40
B29: Humo convencional | C29: =COUNTIFS('Base de Datos SADI'!$C$5:$C$716,C$26,'Base de Datos SADI'!$F$5:$F$716,$B29,'Base de Datos SADI'!$G$5:$G$716,"<>*No disponible*") -> 0 | D29: =COUNTIFS('Base de Datos SADI'!$C$5:$C$716,D$26,'Base de Datos SADI'!$F$5:$F$716,$B29,'Base de Datos SADI'!$G$5:$G$716,"<>*No disponible*") -> 5 | E29: =COUNTIFS('Base de Datos SADI'!$C$5:$C$716,E$26,'Base de Datos SADI'!$F$5:$F$716,$B29,'Base de Datos SADI'!$G$5:$G$716,"<>*No disponible*") -> 5 | F29: =COUNTIFS('Base de Datos SADI'!$C$5:$C$716,F$26,'Base de Datos SADI'!$F$5:$F$716,$B29,'Base de Datos SADI'!$G$5:$G$716,"<>*No disponible*") -> 0 | G29: =COUNTIFS('Base de Datos SADI'!$C$5:$C$716,G$26,'Base de Datos SADI'!$F$5:$F$716,$B29,'Base de Datos SADI'!$G$5:$G$716,"<>*No disponible*") -> 0 | H29: =COUNTIFS('Base de Datos SADI'!$C$5:$C$716,H$26,'Base de Datos SADI'!$F$5:$F$716,$B29,'Base de Datos SADI'!$G$5:$G$716,"<>*No disponible*") -> 5 | I29: =COUNTIFS('Base de Datos SADI'!$C$5:$C$716,I$26,'Base de Datos SADI'!$F$5:$F$716,$B29,'Base de Datos SADI'!$G$5:$G$716,"<>*No disponible*") -> 5 | J29: =COUNTIFS('Base de Datos SADI'!$C$5:$C$716,J$26,'Base de Datos SADI'!$F$5:$F$716,$B29,'Base de Datos SADI'!$G$5:$G$716,"<>*No disponible*") -> 5 | ... R29: =COUNTIFS('Base de Datos SADI'!$C$5:$C$716,R$26,'Base de Datos SADI'!$F$5:$F$716,$B29,'Base de Datos SADI'!$G$5:$G$716,"<>*No disponible*") -> 0 | S29: =SUM(C29:R29) -> 40
B30: Humo direccionable | C30: =COUNTIFS('Base de Datos SADI'!$C$5:$C$716,C$26,'Base de Datos SADI'!$F$5:$F$716,$B30,'Base de Datos SADI'!$G$5:$G$716,"<>*No disponible*") -> 5 | D30: =COUNTIFS('Base de Datos SADI'!$C$5:$C$716,D$26,'Base de Datos SADI'!$F$5:$F$716,$B30,'Base de Datos SADI'!$G$5:$G$716,"<>*No disponible*") -> 5 | E30: =COUNTIFS('Base de Datos SADI'!$C$5:$C$716,E$26,'Base de Datos SADI'!$F$5:$F$716,$B30,'Base de Datos SADI'!$G$5:$G$716,"<>*No disponible*") -> 5 | F30: =COUNTIFS('Base de Datos SADI'!$C$5:$C$716,F$26,'Base de Datos SADI'!$F$5:$F$716,$B30,'Base de Datos SADI'!$G$5:$G$716,"<>*No disponible*") -> 5 | G30: =COUNTIFS('Base de Datos SADI'!$C$5:$C$716,G$26,'Base de Datos SADI'!$F$5:$F$716,$B30,'Base de Datos SADI'!$G$5:$G$716,"<>*No disponible*") -> 5 | H30: =COUNTIFS('Base de Datos SADI'!$C$5:$C$716,H$26,'Base de Datos SADI'!$F$5:$F$716,$B30,'Base de Datos SADI'!$G$5:$G$716,"<>*No disponible*") -> 5 | I30: =COUNTIFS('Base de Datos SADI'!$C$5:$C$716,I$26,'Base de Datos SADI'!$F$5:$F$716,$B30,'Base de Datos SADI'!$G$5:$G$716,"<>*No disponible*") -> 5 | J30: =COUNTIFS('Base de Datos SADI'!$C$5:$C$716,J$26,'Base de Datos SADI'!$F$5:$F$716,$B30,'Base de Datos SADI'!$G$5:$G$716,"<>*No disponible*") -> 5 | ... R30: =COUNTIFS('Base de Datos SADI'!$C$5:$C$716,R$26,'Base de Datos SADI'!$F$5:$F$716,$B30,'Base de Datos SADI'!$G$5:$G$716,"<>*No disponible*") -> 0 | S30: =SUM(C30:R30) -> 55
B31: Térmico direccionable | C31: =COUNTIFS('Base de Datos SADI'!$C$5:$C$716,C$26,'Base de Datos SADI'!$F$5:$F$716,$B31,'Base de Datos SADI'!$G$5:$G$716,"<>*No disponible*") -> 5 | D31: =COUNTIFS('Base de Datos SADI'!$C$5:$C$716,D$26,'Base de Datos SADI'!$F$5:$F$716,$B31,'Base de Datos SADI'!$G$5:$G$716,"<>*No disponible*") -> 5 | E31: =COUNTIFS('Base de Datos SADI'!$C$5:$C$716,E$26,'Base de Datos SADI'!$F$5:$F$716,$B31,'Base de Datos SADI'!$G$5:$G$716,"<>*No disponible*") -> 5 | F31: =COUNTIFS('Base de Datos SADI'!$C$5:$C$716,F$26,'Base de Datos SADI'!$F$5:$F$716,$B31,'Base de Datos SADI'!$G$5:$G$716,"<>*No disponible*") -> 5 | G31: =COUNTIFS('Base de Datos SADI'!$C$5:$C$716,G$26,'Base de Datos SADI'!$F$5:$F$716,$B31,'Base de Datos SADI'!$G$5:$G$716,"<>*No disponible*") -> 5 | H31: =COUNTIFS('Base de Datos SADI'!$C$5:$C$716,H$26,'Base de Datos SADI'!$F$5:$F$716,$B31,'Base de Datos SADI'!$G$5:$G$716,"<>*No disponible*") -> 5 | I31: =COUNTIFS('Base de Datos SADI'!$C$5:$C$716,I$26,'Base de Datos SADI'!$F$5:$F$716,$B31,'Base de Datos SADI'!$G$5:$G$716,"<>*No disponible*") -> 5 | J31: =COUNTIFS('Base de Datos SADI'!$C$5:$C$716,J$26,'Base de Datos SADI'!$F$5:$F$716,$B31,'Base de Datos SADI'!$G$5:$G$716,"<>*No disponible*") -> 5 | ... R31: =COUNTIFS('Base de Datos SADI'!$C$5:$C$716,R$26,'Base de Datos SADI'!$F$5:$F$716,$B31,'Base de Datos SADI'!$G$5:$G$716,"<>*No disponible*") -> 0 | S31: =SUM(C31:R31) -> 50
B32: Multicriterio | C32: =COUNTIFS('Base de Datos SADI'!$C$5:$C$716,C$26,'Base de Datos SADI'!$F$5:$F$716,$B32,'Base de Datos SADI'!$G$5:$G$716,"<>*No disponible*") -> 5 | D32: =COUNTIFS('Base de Datos SADI'!$C$5:$C$716,D$26,'Base de Datos SADI'!$F$5:$F$716,$B32,'Base de Datos SADI'!$G$5:$G$716,"<>*No disponible*") -> 0 | E32: =COUNTIFS('Base de Datos SADI'!$C$5:$C$716,E$26,'Base de Datos SADI'!$F$5:$F$716,$B32,'Base de Datos SADI'!$G$5:$G$716,"<>*No disponible*") -> 5 | F32: =COUNTIFS('Base de Datos SADI'!$C$5:$C$716,F$26,'Base de Datos SADI'!$F$5:$F$716,$B32,'Base de Datos SADI'!$G$5:$G$716,"<>*No disponible*") -> 5 | G32: =COUNTIFS('Base de Datos SADI'!$C$5:$C$716,G$26,'Base de Datos SADI'!$F$5:$F$716,$B32,'Base de Datos SADI'!$G$5:$G$716,"<>*No disponible*") -> 5 | H32: =COUNTIFS('Base de Datos SADI'!$C$5:$C$716,H$26,'Base de Datos SADI'!$F$5:$F$716,$B32,'Base de Datos SADI'!$G$5:$G$716,"<>*No disponible*") -> 0 | I32: =COUNTIFS('Base de Datos SADI'!$C$5:$C$716,I$26,'Base de Datos SADI'!$F$5:$F$716,$B32,'Base de Datos SADI'!$G$5:$G$716,"<>*No disponible*") -> 5 | J32: =COUNTIFS('Base de Datos SADI'!$C$5:$C$716,J$26,'Base de Datos SADI'!$F$5:$F$716,$B32,'Base de Datos SADI'!$G$5:$G$716,"<>*No disponible*") -> 5 | ... R32: =COUNTIFS('Base de Datos SADI'!$C$5:$C$716,R$26,'Base de Datos SADI'!$F$5:$F$716,$B32,'Base de Datos SADI'!$G$5:$G$716,"<>*No disponible*") -> 0 | S32: =SUM(C32:R32) -> 35
B33: Detector de llama | C33: =COUNTIFS('Base de Datos SADI'!$C$5:$C$716,C$26,'Base de Datos SADI'!$F$5:$F$716,$B33,'Base de Datos SADI'!$G$5:$G$716,"<>*No disponible*") -> 0 | D33: =COUNTIFS('Base de Datos SADI'!$C$5:$C$716,D$26,'Base de Datos SADI'!$F$5:$F$716,$B33,'Base de Datos SADI'!$G$5:$G$716,"<>*No disponible*") -> 5 | E33: =COUNTIFS('Base de Datos SADI'!$C$5:$C$716,E$26,'Base de Datos SADI'!$F$5:$F$716,$B33,'Base de Datos SADI'!$G$5:$G$716,"<>*No disponible*") -> 0 | F33: =COUNTIFS('Base de Datos SADI'!$C$5:$C$716,F$26,'Base de Datos SADI'!$F$5:$F$716,$B33,'Base de Datos SADI'!$G$5:$G$716,"<>*No disponible*") -> 0 | G33: =COUNTIFS('Base de Datos SADI'!$C$5:$C$716,G$26,'Base de Datos SADI'!$F$5:$F$716,$B33,'Base de Datos SADI'!$G$5:$G$716,"<>*No disponible*") -> 0 | H33: =COUNTIFS('Base de Datos SADI'!$C$5:$C$716,H$26,'Base de Datos SADI'!$F$5:$F$716,$B33,'Base de Datos SADI'!$G$5:$G$716,"<>*No disponible*") -> 0 | I33: =COUNTIFS('Base de Datos SADI'!$C$5:$C$716,I$26,'Base de Datos SADI'!$F$5:$F$716,$B33,'Base de Datos SADI'!$G$5:$G$716,"<>*No disponible*") -> 0 | J33: =COUNTIFS('Base de Datos SADI'!$C$5:$C$716,J$26,'Base de Datos SADI'!$F$5:$F$716,$B33,'Base de Datos SADI'!$G$5:$G$716,"<>*No disponible*") -> 0 | ... R33: =COUNTIFS('Base de Datos SADI'!$C$5:$C$716,R$26,'Base de Datos SADI'!$F$5:$F$716,$B33,'Base de Datos SADI'!$G$5:$G$716,"<>*No disponible*") -> 5 | S33: =SUM(C33:R33) -> 15
B34: Aspiración (ASD) | C34: =COUNTIFS('Base de Datos SADI'!$C$5:$C$716,C$26,'Base de Datos SADI'!$F$5:$F$716,$B34,'Base de Datos SADI'!$G$5:$G$716,"<>*No disponible*") -> 5 | D34: =COUNTIFS('Base de Datos SADI'!$C$5:$C$716,D$26,'Base de Datos SADI'!$F$5:$F$716,$B34,'Base de Datos SADI'!$G$5:$G$716,"<>*No disponible*") -> 0 | E34: =COUNTIFS('Base de Datos SADI'!$C$5:$C$716,E$26,'Base de Datos SADI'!$F$5:$F$716,$B34,'Base de Datos SADI'!$G$5:$G$716,"<>*No disponible*") -> 0 | F34: =COUNTIFS('Base de Datos SADI'!$C$5:$C$716,F$26,'Base de Datos SADI'!$F$5:$F$716,$B34,'Base de Datos SADI'!$G$5:$G$716,"<>*No disponible*") -> 0 | G34: =COUNTIFS('Base de Datos SADI'!$C$5:$C$716,G$26,'Base de Datos SADI'!$F$5:$F$716,$B34,'Base de Datos SADI'!$G$5:$G$716,"<>*No disponible*") -> 0 | H34: =COUNTIFS('Base de Datos SADI'!$C$5:$C$716,H$26,'Base de Datos SADI'!$F$5:$F$716,$B34,'Base de Datos SADI'!$G$5:$G$716,"<>*No disponible*") -> 0 | I34: =COUNTIFS('Base de Datos SADI'!$C$5:$C$716,I$26,'Base de Datos SADI'!$F$5:$F$716,$B34,'Base de Datos SADI'!$G$5:$G$716,"<>*No disponible*") -> 0 | J34: =COUNTIFS('Base de Datos SADI'!$C$5:$C$716,J$26,'Base de Datos SADI'!$F$5:$F$716,$B34,'Base de Datos SADI'!$G$5:$G$716,"<>*No disponible*") -> 0 | ... R34: =COUNTIFS('Base de Datos SADI'!$C$5:$C$716,R$26,'Base de Datos SADI'!$F$5:$F$716,$B34,'Base de Datos SADI'!$G$5:$G$716,"<>*No disponible*") -> 0 | S34: =SUM(C34:R34) -> 10
B35: Lineal de haz | C35: =COUNTIFS('Base de Datos SADI'!$C$5:$C$716,C$26,'Base de Datos SADI'!$F$5:$F$716,$B35,'Base de Datos SADI'!$G$5:$G$716,"<>*No disponible*") -> 5 | D35: =COUNTIFS('Base de Datos SADI'!$C$5:$C$716,D$26,'Base de Datos SADI'!$F$5:$F$716,$B35,'Base de Datos SADI'!$G$5:$G$716,"<>*No disponible*") -> 0 | E35: =COUNTIFS('Base de Datos SADI'!$C$5:$C$716,E$26,'Base de Datos SADI'!$F$5:$F$716,$B35,'Base de Datos SADI'!$G$5:$G$716,"<>*No disponible*") -> 5 | F35: =COUNTIFS('Base de Datos SADI'!$C$5:$C$716,F$26,'Base de Datos SADI'!$F$5:$F$716,$B35,'Base de Datos SADI'!$G$5:$G$716,"<>*No disponible*") -> 0 | G35: =COUNTIFS('Base de Datos SADI'!$C$5:$C$716,G$26,'Base de Datos SADI'!$F$5:$F$716,$B35,'Base de Datos SADI'!$G$5:$G$716,"<>*No disponible*") -> 0 | H35: =COUNTIFS('Base de Datos SADI'!$C$5:$C$716,H$26,'Base de Datos SADI'!$F$5:$F$716,$B35,'Base de Datos SADI'!$G$5:$G$716,"<>*No disponible*") -> 0 | I35: =COUNTIFS('Base de Datos SADI'!$C$5:$C$716,I$26,'Base de Datos SADI'!$F$5:$F$716,$B35,'Base de Datos SADI'!$G$5:$G$716,"<>*No disponible*") -> 5 | J35: =COUNTIFS('Base de Datos SADI'!$C$5:$C$716,J$26,'Base de Datos SADI'!$F$5:$F$716,$B35,'Base de Datos SADI'!$G$5:$G$716,"<>*No disponible*") -> 0 | ... R35: =COUNTIFS('Base de Datos SADI'!$C$5:$C$716,R$26,'Base de Datos SADI'!$F$5:$F$716,$B35,'Base de Datos SADI'!$G$5:$G$716,"<>*No disponible*") -> 0 | S35: =SUM(C35:R35) -> 20
B36: Estación manual | C36: =COUNTIFS('Base de Datos SADI'!$C$5:$C$716,C$26,'Base de Datos SADI'!$F$5:$F$716,$B36,'Base de Datos SADI'!$G$5:$G$716,"<>*No disponible*") -> 5 | D36: =COUNTIFS('Base de Datos SADI'!$C$5:$C$716,D$26,'Base de Datos SADI'!$F$5:$F$716,$B36,'Base de Datos SADI'!$G$5:$G$716,"<>*No disponible*") -> 5 | E36: =COUNTIFS('Base de Datos SADI'!$C$5:$C$716,E$26,'Base de Datos SADI'!$F$5:$F$716,$B36,'Base de Datos SADI'!$G$5:$G$716,"<>*No disponible*") -> 5 | F36: =COUNTIFS('Base de Datos SADI'!$C$5:$C$716,F$26,'Base de Datos SADI'!$F$5:$F$716,$B36,'Base de Datos SADI'!$G$5:$G$716,"<>*No disponible*") -> 5 | G36: =COUNTIFS('Base de Datos SADI'!$C$5:$C$716,G$26,'Base de Datos SADI'!$F$5:$F$716,$B36,'Base de Datos SADI'!$G$5:$G$716,"<>*No disponible*") -> 5 | H36: =COUNTIFS('Base de Datos SADI'!$C$5:$C$716,H$26,'Base de Datos SADI'!$F$5:$F$716,$B36,'Base de Datos SADI'!$G$5:$G$716,"<>*No disponible*") -> 5 | I36: =COUNTIFS('Base de Datos SADI'!$C$5:$C$716,I$26,'Base de Datos SADI'!$F$5:$F$716,$B36,'Base de Datos SADI'!$G$5:$G$716,"<>*No disponible*") -> 0 | J36: =COUNTIFS('Base de Datos SADI'!$C$5:$C$716,J$26,'Base de Datos SADI'!$F$5:$F$716,$B36,'Base de Datos SADI'!$G$5:$G$716,"<>*No disponible*") -> 5 | ... R36: =COUNTIFS('Base de Datos SADI'!$C$5:$C$716,R$26,'Base de Datos SADI'!$F$5:$F$716,$B36,'Base de Datos SADI'!$G$5:$G$716,"<>*No disponible*") -> 0 | S36: =SUM(C36:R36) -> 55
B37: Sirena con estrobo | C37: =COUNTIFS('Base de Datos SADI'!$C$5:$C$716,C$26,'Base de Datos SADI'!$F$5:$F$716,$B37,'Base de Datos SADI'!$G$5:$G$716,"<>*No disponible*") -> 0 | D37: =COUNTIFS('Base de Datos SADI'!$C$5:$C$716,D$26,'Base de Datos SADI'!$F$5:$F$716,$B37,'Base de Datos SADI'!$G$5:$G$716,"<>*No disponible*") -> 0 | E37: =COUNTIFS('Base de Datos SADI'!$C$5:$C$716,E$26,'Base de Datos SADI'!$F$5:$F$716,$B37,'Base de Datos SADI'!$G$5:$G$716,"<>*No disponible*") -> 0 | F37: =COUNTIFS('Base de Datos SADI'!$C$5:$C$716,F$26,'Base de Datos SADI'!$F$5:$F$716,$B37,'Base de Datos SADI'!$G$5:$G$716,"<>*No disponible*") -> 5 | G37: =COUNTIFS('Base de Datos SADI'!$C$5:$C$716,G$26,'Base de Datos SADI'!$F$5:$F$716,$B37,'Base de Datos SADI'!$G$5:$G$716,"<>*No disponible*") -> 5 | H37: =COUNTIFS('Base de Datos SADI'!$C$5:$C$716,H$26,'Base de Datos SADI'!$F$5:$F$716,$B37,'Base de Datos SADI'!$G$5:$G$716,"<>*No disponible*") -> 0 | I37: =COUNTIFS('Base de Datos SADI'!$C$5:$C$716,I$26,'Base de Datos SADI'!$F$5:$F$716,$B37,'Base de Datos SADI'!$G$5:$G$716,"<>*No disponible*") -> 0 | J37: =COUNTIFS('Base de Datos SADI'!$C$5:$C$716,J$26,'Base de Datos SADI'!$F$5:$F$716,$B37,'Base de Datos SADI'!$G$5:$G$716,"<>*No disponible*") -> 5 | ... R37: =COUNTIFS('Base de Datos SADI'!$C$5:$C$716,R$26,'Base de Datos SADI'!$F$5:$F$716,$B37,'Base de Datos SADI'!$G$5:$G$716,"<>*No disponible*") -> 0 | S37: =SUM(C37:R37) -> 35
B38: Módulo de monitoreo | C38: =COUNTIFS('Base de Datos SADI'!$C$5:$C$716,C$26,'Base de Datos SADI'!$F$5:$F$716,$B38,'Base de Datos SADI'!$G$5:$G$716,"<>*No disponible*") -> 5 | D38: =COUNTIFS('Base de Datos SADI'!$C$5:$C$716,D$26,'Base de Datos SADI'!$F$5:$F$716,$B38,'Base de Datos SADI'!$G$5:$G$716,"<>*No disponible*") -> 5 | E38: =COUNTIFS('Base de Datos SADI'!$C$5:$C$716,E$26,'Base de Datos SADI'!$F$5:$F$716,$B38,'Base de Datos SADI'!$G$5:$G$716,"<>*No disponible*") -> 5 | F38: =COUNTIFS('Base de Datos SADI'!$C$5:$C$716,F$26,'Base de Datos SADI'!$F$5:$F$716,$B38,'Base de Datos SADI'!$G$5:$G$716,"<>*No disponible*") -> 5 | G38: =COUNTIFS('Base de Datos SADI'!$C$5:$C$716,G$26,'Base de Datos SADI'!$F$5:$F$716,$B38,'Base de Datos SADI'!$G$5:$G$716,"<>*No disponible*") -> 5 | H38: =COUNTIFS('Base de Datos SADI'!$C$5:$C$716,H$26,'Base de Datos SADI'!$F$5:$F$716,$B38,'Base de Datos SADI'!$G$5:$G$716,"<>*No disponible*") -> 5 | I38: =COUNTIFS('Base de Datos SADI'!$C$5:$C$716,I$26,'Base de Datos SADI'!$F$5:$F$716,$B38,'Base de Datos SADI'!$G$5:$G$716,"<>*No disponible*") -> 5 | J38: =COUNTIFS('Base de Datos SADI'!$C$5:$C$716,J$26,'Base de Datos SADI'!$F$5:$F$716,$B38,'Base de Datos SADI'!$G$5:$G$716,"<>*No disponible*") -> 5 | ... R38: =COUNTIFS('Base de Datos SADI'!$C$5:$C$716,R$26,'Base de Datos SADI'!$F$5:$F$716,$B38,'Base de Datos SADI'!$G$5:$G$716,"<>*No disponible*") -> 0 | S38: =SUM(C38:R38) -> 50
... B42: Aislador/base lazo | C42: =COUNTIFS('Base de Datos SADI'!$C$5:$C$716,C$26,'Base de Datos SADI'!$F$5:$F$716,$B42,'Base de Datos SADI'!$G$5:$G$716,"<>*No disponible*") -> 5 | D42: =COUNTIFS('Base de Datos SADI'!$C$5:$C$716,D$26,'Base de Datos SADI'!$F$5:$F$716,$B42,'Base de Datos SADI'!$G$5:$G$716,"<>*No disponible*") -> 5 | E42: =COUNTIFS('Base de Datos SADI'!$C$5:$C$716,E$26,'Base de Datos SADI'!$F$5:$F$716,$B42,'Base de Datos SADI'!$G$5:$G$716,"<>*No disponible*") -> 0 | F42: =COUNTIFS('Base de Datos SADI'!$C$5:$C$716,F$26,'Base de Datos SADI'!$F$5:$F$716,$B42,'Base de Datos SADI'!$G$5:$G$716,"<>*No disponible*") -> 5 | G42: =COUNTIFS('Base de Datos SADI'!$C$5:$C$716,G$26,'Base de Datos SADI'!$F$5:$F$716,$B42,'Base de Datos SADI'!$G$5:$G$716,"<>*No disponible*") -> 0 | H42: =COUNTIFS('Base de Datos SADI'!$C$5:$C$716,H$26,'Base de Datos SADI'!$F$5:$F$716,$B42,'Base de Datos SADI'!$G$5:$G$716,"<>*No disponible*") -> 0 | I42: =COUNTIFS('Base de Datos SADI'!$C$5:$C$716,I$26,'Base de Datos SADI'!$F$5:$F$716,$B42,'Base de Datos SADI'!$G$5:$G$716,"<>*No disponible*") -> 5 | J42: =COUNTIFS('Base de Datos SADI'!$C$5:$C$716,J$26,'Base de Datos SADI'!$F$5:$F$716,$B42,'Base de Datos SADI'!$G$5:$G$716,"<>*No disponible*") -> 5 | ... R42: =COUNTIFS('Base de Datos SADI'!$C$5:$C$716,R$26,'Base de Datos SADI'!$F$5:$F$716,$B42,'Base de Datos SADI'!$G$5:$G$716,"<>*No disponible*") -> 0 | S42: =SUM(C42:R42) -> 30
B43: Modelos activos por marca | C43: =SUM(C27:C42) -> 55 | D43: =SUM(D27:D42) -> 55 | E43: =SUM(E27:E42) -> 50 | F43: =SUM(F27:F42) -> 50 | G43: =SUM(G27:G42) -> 45 | H43: =SUM(H27:H42) -> 40 | I43: =SUM(I27:I42) -> 40 | J43: =SUM(J27:J42) -> 50 | ... S43: =SUM(S27:S42) -> 570
B46: Estadísticas SACI por marca (precio USD)
B47: Marca | C47: Nivel | D47: País | E47: Modelos activos | F47: Precio mín. (USD) | G47: Precio máx. (USD) | H47: Precio promedio (USD)
B48: Honeywell Security | C48: Alta | D48: EE. UU. | E48: =COUNTIFS('Base de Datos SACI'!$C$5:$C$1076,$B48,'Base de Datos SACI'!$G$5:$G$1076,"<>*No disponible*") -> 75 | F48: =MIN('Base de Datos SACI'!$U$5:$U$80) -> 8 | G48: =MAX('Base de Datos SACI'!$U$5:$U$80) -> 645 | H48: =IFERROR(ROUND(AVERAGE('Base de Datos SACI'!$U$5:$U$80),0),"—") -> 112
B49: DSC | C49: Alta | D49: Canadá | E49: =COUNTIFS('Base de Datos SACI'!$C$5:$C$1076,$B49,'Base de Datos SACI'!$G$5:$G$1076,"<>*No disponible*") -> 75 | F49: =MIN('Base de Datos SACI'!$U$81:$U$156) -> 12 | G49: =MAX('Base de Datos SACI'!$U$81:$U$156) -> 680 | H49: =IFERROR(ROUND(AVERAGE('Base de Datos SACI'!$U$81:$U$156),0),"—") -> 109
B50: Paradox | C50: Alta | D50: Canadá | E50: =COUNTIFS('Base de Datos SACI'!$C$5:$C$1076,$B50,'Base de Datos SACI'!$G$5:$G$1076,"<>*No disponible*") -> 70 | F50: =MIN('Base de Datos SACI'!$U$157:$U$228) -> 12 | G50: =MAX('Base de Datos SACI'!$U$157:$U$228) -> 625 | H50: =IFERROR(ROUND(AVERAGE('Base de Datos SACI'!$U$157:$U$228),0),"—") -> 94
B51: Bosch Security | C51: Alta | D51: Alemania | E51: =COUNTIFS('Base de Datos SACI'!$C$5:$C$1076,$B51,'Base de Datos SACI'!$G$5:$G$1076,"<>*No disponible*") -> 65 | F51: =MIN('Base de Datos SACI'!$U$229:$U$296) -> 16 | G51: =MAX('Base de Datos SACI'!$U$229:$U$296) -> 580 | H51: =IFERROR(ROUND(AVERAGE('Base de Datos SACI'!$U$229:$U$296),0),"—") -> 122
B52: Ajax Systems | C52: Alta | D52: Ucrania | E52: =COUNTIFS('Base de Datos SACI'!$C$5:$C$1076,$B52,'Base de Datos SACI'!$G$5:$G$1076,"<>*No disponible*") -> 65 | F52: =MIN('Base de Datos SACI'!$U$297:$U$364) -> 12 | G52: =MAX('Base de Datos SACI'!$U$297:$U$364) -> 680 | H52: =IFERROR(ROUND(AVERAGE('Base de Datos SACI'!$U$297:$U$364),0),"—") -> 88
B53: Visonic | C53: Alta | D53: Israel | E53: =COUNTIFS('Base de Datos SACI'!$C$5:$C$1076,$B53,'Base de Datos SACI'!$G$5:$G$1076,"<>*No disponible*") -> 65 | F53: =MIN('Base de Datos SACI'!$U$365:$U$432) -> 8 | G53: =MAX('Base de Datos SACI'!$U$365:$U$432) -> 645 | H53: =IFERROR(ROUND(AVERAGE('Base de Datos SACI'!$U$365:$U$432),0),"—") -> 88
...

Sheet Base de Datos SACI
B2: Base de Datos Técnica — SACI · Sistemas de Alarma Contra Intrusos (18 marcas × 16 tipos × 5 variantes)
B4: N° | C4: Marca | D4: Nivel | E4: País | F4: Tipo de Dispositivo | G4: Modelo | H4: Capacidad / Alcance | I4: Tecnología de Detección | J4: Anti-Falsa Alarma / Inmunidad | K4: Comunicación de Eventos | L4: Protocolo / Frecuencia | M4: Alimentación | N4: Consumo | O4: Protección | P4: Temp. Operación | Q4: Dimensiones | R4: Peso | S4: Certificaciones | T4: Uso Recomendado | U4: Precio Ref. (USD) | V4: Proveedor | W4: Stock | X4: Observaciones | Y4: Consumo en Reposo (A) | Z4: Consumo en Alarma (A) | AA4: Tensión de Alimentación (V) | AB4: Protocolos Compatibles | AC4: Centrales Compatibles | AD4: Consumo en Reposo de la Central (A) | AE4: Consumo en Alarma de la Central (A) | AF4: Corriente Nominal de la Fuente (A) | AG4: Zonas de la Central | AH4: Particiones | AI4: Área de Cobertura (m²) | AJ4: Radio de Cobertura (m) | AK4: Alcance (m) | AL4: Apertura del Sector (grados) | AM4: Forma de Cobertura | AN4: Potencia Acústica (W) | AO4: Altura Mínima de Montaje (m) | AP4: Altura Máxima de Montaje (m)
B5: 1 | C5: Honeywell Security | D5: Alta | E5: EE. UU. | F5: Panel híbrido | G5: VISTA-20P | H5: 128 zonas / 8 particiones | I5: Híbrido: 8 zonas alámbricas de base + bus ECP | J5: Auto-Stay / Instant; detección de sabotaje por zona | K5: Contact ID a central o CSDC | L5: Contact ID / SIA DC-09 (AlarmNet) | M5: 16.5 VAC 40 VA · batería 12 V 7 Ah | N5: 700 mA máx con respaldo | O5: — | P5: 0 °C a +49 °C | Q5: 312 × 360 × 80 mm | R5: 3.4 kg | S5: UL 1023/1610, CE, FCC | T5: Residencial y comercial mediano | U5: 145 | X5: Variante económica de la gama | Y5: 0.08 | Z5: 0.7 | AA5: 12 | AB5: Contact ID / SIA DC-09 (AlarmNet) | AC5: Central maestra — admite periféricos del ecosistema VISTA/ProA7 (bus ECP) | AD5: 0.08 | AE5: 0.7 | AF5: 1.7 | AG5: 8 | AH5: 2 | AI5: N/A | AJ5: N/A | AK5: N/A | AL5: N/A | AM5: N/A | AN5: N/A | AO5: N/A | AP5: N/A
B6: 2 | C6: Honeywell Security | D6: Alta | E6: EE. UU. | F6: Panel híbrido | G6: VISTA-48LA | H6: 128 zonas / 8 particiones | I6: Híbrido: 8 zonas alámbricas de base + bus ECP | J6: Auto-Stay / Instant; detección de sabotaje por zona | K6: Contact ID a central o CSDC | L6: Contact ID / SIA DC-09 (AlarmNet) | M6: 16.5 VAC 40 VA · batería 12 V 7 Ah | N6: 700 mA máx con respaldo | O6: — | P6: 0 °C a +49 °C | Q6: 312 × 360 × 80 mm | R6: 3.4 kg | S6: UL 1023/1610, CE, FCC | T6: Residencial y comercial mediano | U6: 220 | X6: Gama de entrada | Y6: 0.079 | Z6: 0.7 | AA6: 12 | AB6: Contact ID / SIA DC-09 (AlarmNet) | AC6: Central maestra — admite periféricos del ecosistema VISTA/ProA7 (bus ECP) | AD6: 0.079 | AE6: 0.7 | AF6: 3 | AG6: 48 | AH6: 4 | AI6: N/A | AJ6: N/A | AK6: N/A | AL6: N/A | AM6: N/A | AN6: N/A | AO6: N/A | AP6: N/A
B7: 3 | C7: Honeywell Security | D7: Alta | E7: EE. UU. | F7: Panel híbrido | G7: VISTA-128BPT | H7: 128 zonas / 8 particiones | I7: Híbrido: 8 zonas alámbricas de base + bus ECP | J7: Auto-Stay / Instant; detección de sabotaje por zona | K7: Contact ID a central o CSDC | L7: Contact ID / SIA DC-09 (AlarmNet) | M7: 16.5 VAC 40 VA · batería 12 V 7 Ah | N7: 700 mA máx con respaldo | O7: — | P7: 0 °C a +49 °C | Q7: 312 × 360 × 80 mm | R7: 3.4 kg | S7: UL 1023/1610, CE, FCC | T7: Residencial y comercial mediano | U7: 295 | X7: Panel clásico del mercado, expansión modular ECP | Y7: 0.101 | Z7: 0.7 | AA7: 12 | AB7: Contact ID / SIA DC-09 (AlarmNet) | AC7: Central maestra — admite periféricos del ecosistema VISTA/ProA7 (bus ECP) | AD7: 0.101 | AE7: 0.7 | AF7: 3.5 | AG7: 128 | AH7: 8 | AI7: N/A | AJ7: N/A | AK7: N/A | AL7: N/A | AM7: N/A | AN7: N/A | AO7: N/A | AP7: N/A
B8: 4 | C8: Honeywell Security | D8: Alta | E8: EE. UU. | F8: Panel híbrido | G8: VISTA-128FBP | H8: 128 zonas / 8 particiones | I8: Híbrido: 8 zonas alámbricas de base + bus ECP | J8: Auto-Stay / Instant; detección de sabotaje por zona | K8: Contact ID a central o CSDC | L8: Contact ID / SIA DC-09 (AlarmNet) | M8: 16.5 VAC 40 VA · batería 12 V 7 Ah | N8: 700 mA máx con respaldo | O8: — | P8: 0 °C a +49 °C | Q8: 312 × 360 × 80 mm | R8: 3.4 kg | S8: UL 1023/1610, CE, FCC | T8: Residencial y comercial mediano | U8: 440 | X8: Capacidad y rendimiento mejorados | Y8: 0.054 | Z8: 0.7 | AA8: 12 | AB8: Contact ID / SIA DC-09 (AlarmNet) | AC8: Central maestra — admite periféricos del ecosistema VISTA/ProA7 (bus ECP) | AD8: 0.054 | AE8: 0.7 | AF8: 3.5 | AG8: 128 | AH8: 8 | AI8: N/A | AJ8: N/A | AK8: N/A | AL8: N/A | AM8: N/A | AN8: N/A | AO8: N/A | AP8: N/A
B9: 5 | C9: Honeywell Security | D9: Alta | E9: EE. UU. | F9: Panel híbrido | G9: ProA7Plus | H9: 128 zonas / 8 particiones | I9: Híbrido: 8 zonas alámbricas de base + bus ECP | J9: Auto-Stay / Instant; detección de sabotaje por zona | K9: Contact ID a central o CSDC | L9: Contact ID / SIA DC-09 (AlarmNet) | M9: 16.5 VAC 40 VA · batería 12 V 7 Ah | N9: 700 mA máx con respaldo | O9: — | P9: 0 °C a +49 °C | Q9: 312 × 360 × 80 mm | R9: 3.4 kg | S9: UL 1023/1610, CE, FCC | T9: Residencial y comercial mediano | U9: 645 | X9: Tope de gama — máxima especificación | Y9: 0.079 | Z9: 0.7 | AA9: 12 | AB9: Contact ID / SIA DC-09 (AlarmNet) | AC9: Central maestra — admite periféricos del ecosistema VISTA/ProA7 (bus ECP) | AD9: 0.079 | AE9: 0.7 | AF9: 3.5 | AG9: 100 | AH9: 4 | AI9: N/A | AJ9: N/A | AK9: N/A | AL9: N/A | AM9: N/A | AN9: N/A | AO9: N/A | AP9: N/A
B10: 6 | C10: Honeywell Security | D10: Alta | E10: EE. UU. | F10: Panel alámbrico | G10: VISTA-20P | H10: 48 zonas / 4 particiones | I10: Alámbrico con expansión inalámbrica 5800 opcional | J10: Detección de sabotaje, salida PGM programable | K10: Contact ID integrado (dialer 56k) | L10: Contact ID / SIA DC-09 (AlarmNet) | M10: 16.5 VAC 40 VA · batería 12 V 7 Ah | N10: 600 mA máx | O10: — | P10: 0 °C a +49 °C | Q10: 262 × 300 × 78 mm | R10: 2.6 kg | S10: UL 1023/1610, CE, FCC | T10: Residencial y PYME | U10: 85 | X10: Variante económica de la gama | Y10: 0.08 | Z10: 0.6 | AA10: 12 | AB10: Contact ID / SIA DC-09 (AlarmNet) | AC10: Central maestra — admite periféricos del ecosistema VISTA/ProA7 (bus ECP) | AD10: 0.08 | AE10: 0.6 | AF10: 1.7 | AG10: 8 | AH10: 2 | AI10: N/A | AJ10: N/A | AK10: N/A | AL10: N/A | AM10: N/A | AN10: N/A | AO10: N/A | AP10: N/A
B11: 7 | C11: Honeywell Security | D11: Alta | E11: EE. UU. | F11: Panel alámbrico | G11: VISTA-48LA | H11: 48 zonas / 4 particiones | I11: Alámbrico con expansión inalámbrica 5800 opcional | J11: Detección de sabotaje, salida PGM programable | K11: Contact ID integrado (dialer 56k) | L11: Contact ID / SIA DC-09 (AlarmNet) | M11: 16.5 VAC 40 VA · batería 12 V 7 Ah | N11: 600 mA máx | O11: — | P11: 0 °C a +49 °C | Q11: 262 × 300 × 78 mm | R11: 2.6 kg | S11: UL 1023/1610, CE, FCC | T11: Residencial y PYME | U11: 130 | X11: Gama de entrada | Y11: 0.079 | Z11: 0.6 | AA11: 12 | AB11: Contact ID / SIA DC-09 (AlarmNet) | AC11: Central maestra — admite periféricos del ecosistema VISTA/ProA7 (bus ECP) | AD11: 0.079 | AE11: 0.6 | AF11: 3 | AG11: 48 | AH11: 4 | AI11: N/A | AJ11: N/A | AK11: N/A | AL11: N/A | AM11: N/A | AN11: N/A | AO11: N/A | AP11: N/A
B12: 8 | C12: Honeywell Security | D12: Alta | E12: EE. UU. | F12: Panel alámbrico | G12: VISTA-128BPT | H12: 48 zonas / 4 particiones | I12: Alámbrico con expansión inalámbrica 5800 opcional | J12: Detección de sabotaje, salida PGM programable | K12: Contact ID integrado (dialer 56k) | L12: Contact ID / SIA DC-09 (AlarmNet) | M12: 16.5 VAC 40 VA · batería 12 V 7 Ah | N12: 600 mA máx | O12: — | P12: 0 °C a +49 °C | Q12: 262 × 300 × 78 mm | R12: 2.6 kg | S12: UL 1023/1610, CE, FCC | T12: Residencial y PYME | U12: 175 | X12: Versión latinoamericana del VISTA 48 | Y12: 0.101 | Z12: 0.6 | AA12: 12 | AB12: Contact ID / SIA DC-09 (AlarmNet) | AC12: Central maestra — admite periféricos del ecosistema VISTA/ProA7 (bus ECP) | AD12: 0.101 | AE12: 0.6 | AF12: 3.5 | AG12: 128 | AH12: 8 | AI12: N/A | AJ12: N/A | AK12: N/A | AL12: N/A | AM12: N/A | AN12: N/A | AO12: N/A | AP12: N/A
B13: 9 | C13: Honeywell Security | D13: Alta | E13: EE. UU. | F13: Panel alámbrico | G13: VISTA-250FBP | H13: 48 zonas / 4 particiones | I13: Alámbrico con expansión inalámbrica 5800 opcional | J13: Detección de sabotaje, salida PGM programable | K13: Contact ID integrado (dialer 56k) | L13: Contact ID / SIA DC-09 (AlarmNet) | M13: 16.5 VAC 40 VA · batería 12 V 7 Ah | N13: 600 mA máx | O13: — | P13: 0 °C a +49 °C | Q13: 262 × 300 × 78 mm | R13: 2.6 kg | S13: UL 1023/1610, CE, FCC | T13: Residencial y PYME | U13: 260 | X13: Capacidad y rendimiento mejorados | Y13: 0.102 | Z13: 0.6 | AA13: 12 | AB13: Contact ID / SIA DC-09 (AlarmNet) | AC13: Central maestra — admite periféricos del ecosistema VISTA/ProA7 (bus ECP) | AD13: 0.102 | AE13: 0.6 | AF13: 3.5 | AG13: 250 | AH13: 8 | AI13: N/A | AJ13: N/A | AK13: N/A | AL13: N/A | AM13: N/A | AN13: N/A | AO13: N/A | AP13: N/A
B14: 10 | C14: Honeywell Security | D14: Alta | E14: EE. UU. | F14: Panel alámbrico | G14: ProA7Plus | H14: 48 zonas / 4 particiones | I14: Alámbrico con expansión inalámbrica 5800 opcional | J14: Detección de sabotaje, salida PGM programable | K14: Contact ID integrado (dialer 56k) | L14: Contact ID / SIA DC-09 (AlarmNet) | M14: 16.5 VAC 40 VA · batería 12 V 7 Ah | N14: 600 mA máx | O14: — | P14: 0 °C a +49 °C | Q14: 262 × 300 × 78 mm | R14: 2.6 kg | S14: UL 1023/1610, CE, FCC | T14: Residencial y PYME | U14: 385 | X14: Tope de gama — máxima especificación | Y14: 0.079 | Z14: 0.6 | AA14: 12 | AB14: Contact ID / SIA DC-09 (AlarmNet) | AC14: Central maestra — admite periféricos del ecosistema VISTA/ProA7 (bus ECP) | AD14: 0.079 | AE14: 0.6 | AF14: 3.5 | AG14: 100 | AH14: 4 | AI14: N/A | AJ14: N/A | AK14: N/A | AL14: N/A | AM14: N/A | AN14: N/A | AO14: N/A | AP14: N/A
B15: 11 | C15: Honeywell Security | D15: Alta | E15: EE. UU. | F15: Panel inalámbrico / Hub | G15: ProA7 | H15: Hasta 100 zonas inalámbricas | I15: Inalámbrico 319.5 MHz con radio SiX | J15: Cifrado SiX Two-Way, foto-verificación | K15: LTE + Wi-Fi integrado (AlarmNet) | L15: Contact ID / SIA DC-09 (AlarmNet) | M15: 26 VAC 40 VA · batería 12 V | N15: 450 mA máx | O15: — | P15: 0 °C a +49 °C | Q15: 250 × 230 × 75 mm | R15: 2.2 kg | S15: UL 1023/1610, CE, FCC | T15: Residencial smart | U15: 130 | X15: Variante económica de la gama | Y15: 0.075 | Z15: 0.45 | AA15: 12 | AB15: Contact ID / SIA DC-09 (AlarmNet) | AC15: Central maestra — admite periféricos del ecosistema VISTA/ProA7 (bus ECP) | AD15: 0.075 | AE15: 0.45 | AF15: 2 | AG15: 100 | AH15: 4 | AI15: N/A | AJ15: N/A | AK15: N/A | AL15: N/A | AM15: N/A | AN15: N/A | AO15: N/A | AP15: N/A
B16: 12 | C16: Honeywell Security | D16: Alta | E16: EE. UU. | F16: Panel inalámbrico / Hub | G16: ProA7Plus | H16: Hasta 100 zonas inalámbricas | I16: Inalámbrico 319.5 MHz con radio SiX | J16: Cifrado SiX Two-Way, foto-verificación | K16: LTE + Wi-Fi integrado (AlarmNet) | L16: Contact ID / SIA DC-09 (AlarmNet) | M16: 26 VAC 40 VA · batería 12 V | N16: 450 mA máx | O16: — | P16: 0 °C a +49 °C | Q16: 250 × 230 × 75 mm | R16: 2.2 kg | S16: UL 1023/1610, CE, FCC | T16: Residencial smart | U16: 195 | X16: Gama de entrada | Y16: 0.079 | Z16: 0.45 | AA16: 12 | AB16: Contact ID / SIA DC-09 (AlarmNet) | AC16: Central maestra — admite periféricos del ecosistema VISTA/ProA7 (bus ECP) | AD16: 0.079 | AE16: 0.45 | AF16: 2 | AG16: 100 | AH16: 4 | AI16: N/A | AJ16: N/A | AK16: N/A | AL16: N/A | AM16: N/A | AN16: N/A | AO16: N/A | AP16: N/A
... B19: 15 | C19: Honeywell Security | D19: Alta | E19: EE. UU. | F19: Panel inalámbrico / Hub | G19: L5000C | H19: Hasta 100 zonas inalámbricas | I19: Inalámbrico 319.5 MHz con radio SiX | J19: Cifrado SiX Two-Way, foto-verificación | K19: LTE + Wi-Fi integrado (AlarmNet) | L19: Contact ID / SIA DC-09 (AlarmNet) | M19: 26 VAC 40 VA · batería 12 V | N19: 450 mA máx | O19: — | P19: 0 °C a +49 °C | Q19: 250 × 230 × 75 mm | R19: 2.2 kg | S19: UL 1023/1610, CE, FCC | T19: Residencial smart | U19: 580 | X19: Tope de gama — máxima especificación | Y19: 0.055 | Z19: 0.45 | AA19: 12 | AB19: Contact ID / SIA DC-09 (AlarmNet) | AC19: Central maestra — admite periféricos del ecosistema VISTA/ProA7 (bus ECP) | AD19: 0.055 | AE19: 0.45 | AF19: 2 | AG19: 100 | AH19: 4 | AI19: N/A | AJ19: N/A | AK19: N/A | AL19: N/A | AM19: N/A | AN19: N/A | AO19: N/A | AP19: N/A
B20: 16 | C20: Honeywell Security | D20: Alta | E20: EE. UU. | F20: Teclado de control | G20: 6150 | H20: Controla hasta 48 zonas del sistema | I20: Teclado alfanumérico LCD 2×16 | J20: Transceptor 5800 integrado para zonas inalámbricas | K20: Bus ECP | L20: Contact ID / SIA DC-09 (AlarmNet) | M20: 12 VDC desde panel | N20: 110 mA | O20: — | P20: 0 °C a +49 °C | Q20: 146 × 111 × 32 mm | R20: 310 g | S20: UL 1023/1610, CE, FCC | T20: Uso general | U20: 45 | X20: Variante económica de la gama | Y20: 0.039 | Z20: 0.075 | AA20: 12 | AB20: Contact ID / SIA DC-09 (AlarmNet) | AC20: Centrales VISTA/ProA7 (bus ECP) (mismo bus) | AD20: N/A | AE20: N/A | AF20: N/A | AG20: N/A | AH20: N/A | AI20: N/A | AJ20: N/A | AK20: N/A | AL20: N/A | AM20: N/A | AN20: N/A | AO20: 1.2 | AP20: 1.6
B21: 17 | C21: Honeywell Security | D21: Alta | E21: EE. UU. | F21: Teclado de control | G21: 6150RF | H21: Controla hasta 48 zonas del sistema | I21: Teclado alfanumérico LCD 2×16 | J21: Transceptor 5800 integrado para zonas inalámbricas | K21: Bus ECP | L21: Contact ID / SIA DC-09 (AlarmNet) | M21: 12 VDC desde panel | N21: 110 mA | O21: — | P21: 0 °C a +49 °C | Q21: 146 × 111 × 32 mm | R21: 310 g | S21: UL 1023/1610, CE, FCC | T21: Uso general | U21: 70 | X21: Gama de entrada | Y21: 0.048 | Z21: 0.09 | AA21: 12 | AB21: Contact ID / SIA DC-09 (AlarmNet) | AC21: Centrales VISTA/ProA7 (bus ECP) (mismo bus) | AD21: N/A | AE21: N/A | AF21: N/A | AG21: N/A | AH21: N/A | AI21: N/A | AJ21: N/A | AK21: N/A | AL21: N/A | AM21: N/A | AN21: N/A | AO21: 1.2 | AP21: 1.6
B22: 18 | C22: Honeywell Security | D22: Alta | E22: EE. UU. | F22: Teclado de control | G22: 6160RF | H22: Controla hasta 48 zonas del sistema | I22: Teclado alfanumérico LCD 2×16 | J22: Transceptor 5800 integrado para zonas inalámbricas | K22: Bus ECP | L22: Contact ID / SIA DC-09 (AlarmNet) | M22: 12 VDC desde panel | N22: 110 mA | O22: — | P22: 0 °C a +49 °C | Q22: 146 × 111 × 32 mm | R22: 310 g | S22: UL 1023/1610, CE, FCC | T22: Uso general | U22: 95 | X22: Teclado premium con proximity opcional | Y22: 0.046 | Z22: 0.087 | AA22: 12 | AB22: Contact ID / SIA DC-09 (AlarmNet) | AC22: Centrales VISTA/ProA7 (bus ECP) (mismo bus) | AD22: N/A | AE22: N/A | AF22: N/A | AG22: N/A | AH22: N/A | AI22: N/A | AJ22: N/A | AK22: N/A | AL22: N/A | AM22: N/A | AN22: N/A | AO22: 1.2 | AP22: 1.6
